<?xml version="1.0" ?>
<!-- =================================================================================== -->
<!-- |    This document was autogenerated by xacro from /home/fmw-ws/git/care-o-bot/cob_robots/cob_hardware_config/lwa_ext_sdh/urdf/lwa_ext_sdh.urdf.xacro | -->
<!-- |    EDITING THIS FILE BY HAND IS NOT RECOMMENDED                                 | -->
<!-- =================================================================================== -->
<robot name="lwa" xmlns:controller="http://playerstage.sourceforge.net/gazebo/xmlschema/#controller" xmlns:interface="http://playerstage.sourceforge.net/gazebo/xmlschema/#interface" xmlns:sensor="http://playerstage.sourceforge.net/gazebo/xmlschema/#sensor" xmlns:xacro="http://ros.org/wiki/xacro">
  <!-- common stuff -->
  <material name="Blue">
    <color rgba="0.0 0.0 0.8 1.0"/>
  </material>
  <material name="Green">
    <color rgba="0.0 0.8 0.0 1.0"/>
  </material>
  <material name="Grey">
    <color rgba="0.7 0.7 0.7 1.0"/>
  </material>
  <material name="Grey2">
    <color rgba="0.9 0.9 0.9 1.0"/>
  </material>
  <material name="Red">
    <color rgba="0.8 0.0 0.0 1.0"/>
  </material>
  <material name="White">
    <color rgba="1.0 1.0 1.0 1.0"/>
  </material>
  <material name="Black">
    <color rgba="0.0 0.0 0.0 1.0"/>
  </material>
  <material name="Caster">
    <texture filename="package://pr2_ogre/Media/materials/textures/pr2_caster_texture.png"/>
  </material>
  <material name="Wheel_l">
    <texture filename="package://pr2_ogre/Media/materials/textures/pr2_wheel_left.png"/>
  </material>
  <material name="Wheel_r">
    <texture filename="package://pr2_ogre/Media/materials/textures/pr2_wheel_right.png"/>
  </material>
  <material name="RollLinks">
    <texture filename="package://pr2_ogre/Media/materials/textures/pr2_wheel_left.png"/>
  </material>
  <!-- calibration -->
  <!-- schunk lwa_extended -->
  <!-- sdh-->
  <!-- generic simulator_gazebo plugins for starting mechanism control, ros time, ros battery -->
  <!--include filename="$(find cob_description)/ros/gazebo/gazebo.urdf.xacro" /-->
  <!-- tof camera -->
  <!-- foot for arm -->
  <link name="base_link">
    <inertial>
      <origin rpy="0 0 0" xyz="0 0 -10"/>
      <mass value="1000.0"/>
      <inertia ixx="100.0" ixy="0" ixz="0" iyy="100.0" iyz="0" izz="100.0"/>
    </inertial>
    <visual>
      <origin rpy="0 0 0" xyz="0 0 0.255"/>
      <geometry>
        <cylinder length="0.51" radius="0.05"/>
      </geometry>
      <material name="Grey"/>
    </visual>
    <collision>
      <origin rpy="0 0 0" xyz="0 0 0.255"/>
      <geometry>
        <cylinder length="0.51" radius="0.05"/>
      </geometry>
    </collision>
  </link>
  <!-- arm -->
  <joint name="arm_0_joint" type="fixed">
    <origin rpy="3.1415926 0 0" xyz="0 0 0.53"/>
    <parent link="base_link"/>
    <child link="arm_0_link"/>
  </joint>
  <link name="arm_0_link">
    <inertial>
      <origin rpy="0 0 0" xyz="0 0 0"/>
      <mass value="1.0"/>
      <inertia ixx="0.01" ixy="0" ixz="0" iyy="0.01" iyz="0" izz="0.01"/>
    </inertial>
    <visual>
      <origin rpy="0 0 0" xyz="0 0 0.004"/>
      <geometry>
        <cylinder length="0.08" radius="0.045"/>
      </geometry>
      <material name="Red"/>
    </visual>
    <collision>
      <origin rpy="0 0 0" xyz="0 0 0.005"/>
      <geometry>
        <box size="0.01 0.01 0.01"/>
      </geometry>
    </collision>
  </link>
  <joint name="arm_1_joint" type="revolute">
    <origin rpy="0 0 3.1415926" xyz="0 0 -0.30"/>
    <parent link="arm_0_link"/>
    <child link="arm_1_link"/>
    <axis xyz="0 0 1"/>
    <calibration rising="-1.299"/>
    <dynamics damping="10"/>
    <limit effort="370" lower="-6.2831853" upper="6.2831853" velocity="2.0"/>
    <safety_controller k_position="20" k_velocity="50" soft_lower_limit="-6.2731853" soft_upper_limit="6.2731853"/>
  </joint>
  <link name="arm_1_link">
    <inertial>
      <origin rpy="0 0 0" xyz="0 0 0"/>
      <!--mass value="5.9907"/-->
      <mass value="2.0"/>
      <inertia ixx="0.01" ixy="0" ixz="0" iyy="0.01" iyz="0" izz="0.01"/>
    </inertial>
    <visual>
      <origin rpy="0 0 0" xyz="0 0 0"/>
      <geometry>
        <mesh filename="package://schunk_description/meshes/lwa/lwa1.stl"/>
      </geometry>
      <material name="Blue"/>
    </visual>
    <collision>
      <origin rpy="0 0 0" xyz="0 0 0"/>
      <geometry>
        <mesh filename="package://schunk_description/meshes/lwa/lwa1.stlb"/>
      </geometry>
    </collision>
  </link>
  <joint name="arm_2_joint" type="revolute">
    <origin rpy="1.5708 0 0" xyz="0 0 0"/>
    <parent link="arm_1_link"/>
    <child link="arm_2_link"/>
    <axis xyz="0 0 1"/>
    <calibration rising="0.038"/>
    <dynamics damping="10"/>
    <limit effort="370" lower="-2.0943951" upper="2.0943951" velocity="2.0"/>
    <safety_controller k_position="20" k_velocity="50" soft_lower_limit="-2.0843" soft_upper_limit="2.0843"/>
  </joint>
  <link name="arm_2_link">
    <inertial>
      <origin rpy="0 0 0" xyz="0 0 0"/>
      <!--mass value="5.734939"/-->
      <mass value="2.0"/>
      <inertia ixx="0.03" ixy="0" ixz="0" iyy="0.03" iyz="0" izz="0.03"/>
    </inertial>
    <visual>
      <origin rpy="0 0 0" xyz="0 0 0"/>
      <geometry>
        <mesh filename="package://schunk_description/meshes/lwa/lwa2.stl"/>
      </geometry>
      <material name="Red"/>
    </visual>
    <collision>
      <origin rpy="0 0 0" xyz="0 0 0"/>
      <geometry>
        <mesh filename="package://schunk_description/meshes/lwa/lwa2.stlb"/>
      </geometry>
    </collision>
  </link>
  <joint name="arm_3_joint" type="revolute">
    <origin rpy="-1.5708 0 0" xyz="0 -0.403 0"/>
    <parent link="arm_2_link"/>
    <child link="arm_3_link"/>
    <axis xyz="0 0 1"/>
    <calibration rising="-0.1"/>
    <dynamics damping="5"/>
    <limit effort="176" lower="-6.2831853" upper="6.2831853" velocity="2.0"/>
    <safety_controller k_position="20" k_velocity="25" soft_lower_limit="-6.2731853" soft_upper_limit="6.2731853"/>
  </joint>
  <link name="arm_3_link">
    <inertial>
      <origin rpy="0 0 0" xyz="0 0 0"/>
      <!--mass value="4.214668"/-->
      <mass value="2.0"/>
      <inertia ixx="0.03" ixy="0" ixz="0" iyy="0.03" iyz="0" izz="0.03"/>
    </inertial>
    <visual>
      <origin rpy="0 0 0" xyz="0 0 0"/>
      <geometry>
        <mesh filename="package://schunk_description/meshes/lwa/lwa3.stl"/>
      </geometry>
      <material name="Blue"/>
    </visual>
    <collision>
      <origin rpy="0 0 0" xyz="0 0 0"/>
      <geometry>
        <mesh filename="package://schunk_description/meshes/lwa/lwa3.stlb"/>
      </geometry>
    </collision>
  </link>
  <joint name="arm_4_joint" type="revolute">
    <origin rpy="1.5708 0 0" xyz="0 0 0"/>
    <parent link="arm_3_link"/>
    <child link="arm_4_link"/>
    <axis xyz="0 0 1"/>
    <calibration rising="-0.034"/>
    <dynamics damping="5"/>
    <limit effort="176" lower="-2.0943951" upper="2.0943951" velocity="2.0"/>
    <safety_controller k_position="20" k_velocity="25" soft_lower_limit="-2.0843951" soft_upper_limit="2.0843951"/>
  </joint>
  <link name="arm_4_link">
    <inertial>
      <origin rpy="0 0 0" xyz="0 0 0"/>
      <!--mass value="3.669819"/-->
      <mass value="2.0"/>
      <inertia ixx="0.03" ixy="0" ixz="0" iyy="0.03" iyz="0" izz="0.03"/>
    </inertial>
    <visual>
      <origin rpy="0 0 0" xyz="0 0 0"/>
      <geometry>
        <mesh filename="package://schunk_description/meshes/lwa/lwa4.stl"/>
      </geometry>
      <material name="Red"/>
    </visual>
    <collision>
      <origin rpy="0 0 0" xyz="0 0 0"/>
      <geometry>
        <mesh filename="package://schunk_description/meshes/lwa/lwa4.stlb"/>
      </geometry>
    </collision>
  </link>
  <joint name="arm_5_joint" type="revolute">
    <origin rpy="-1.5708 0 0" xyz="0 -0.3265 0"/>
    <parent link="arm_4_link"/>
    <child link="arm_5_link"/>
    <axis xyz="0 0 1"/>
    <calibration rising="-0.1"/>
    <dynamics damping="5"/>
    <limit effort="41.6" lower="-6.2831853" upper="6.2831853" velocity="2.0"/>
    <safety_controller k_position="20" k_velocity="25" soft_lower_limit="-6.2731853" soft_upper_limit="6.2731853"/>
  </joint>
  <link name="arm_5_link">
    <inertial>
      <origin rpy="0 0 0" xyz="0 0 0"/>
      <mass value="2.313272"/>
      <inertia ixx="0.03" ixy="0" ixz="0" iyy="0.03" iyz="0" izz="0.03"/>
    </inertial>
    <visual>
      <origin rpy="0 0 0" xyz="0 0 0"/>
      <geometry>
        <mesh filename="package://schunk_description/meshes/lwa/lwa5.stl"/>
      </geometry>
      <material name="Blue"/>
    </visual>
    <collision>
      <origin rpy="0 0 0" xyz="0 0 0"/>
      <geometry>
        <mesh filename="package://schunk_description/meshes/lwa/lwa5.stlb"/>
      </geometry>
    </collision>
  </link>
  <joint name="arm_6_joint" type="revolute">
    <origin rpy="1.5708 0 0" xyz="0 0 0"/>
    <parent link="arm_5_link"/>
    <child link="arm_6_link"/>
    <axis xyz="0 0 1"/>
    <calibration rising="0.0"/>
    <dynamics damping="5"/>
    <limit effort="20.1" lower="-2.0943951" upper="2.0943951" velocity="2.0"/>
    <safety_controller k_position="20" k_velocity="25" soft_lower_limit="-2.0843951" soft_upper_limit="2.0843951"/>
  </joint>
  <link name="arm_6_link">
    <inertial>
      <origin rpy="0 0 0" xyz="0 0 0"/>
      <mass value="2.057856"/>
      <inertia ixx="0.01" ixy="0" ixz="0" iyy="0.01" iyz="0" izz="0.01"/>
    </inertial>
    <visual>
      <origin rpy="0 0 0" xyz="0 0 0"/>
      <geometry>
        <mesh filename="package://schunk_description/meshes/lwa/lwa6.stl"/>
      </geometry>
      <material name="Red"/>
    </visual>
    <collision>
      <origin rpy="0 0 0" xyz="0 0 0"/>
      <geometry>
        <mesh filename="package://schunk_description/meshes/lwa/lwa6.stlb"/>
      </geometry>
    </collision>
  </link>
  <joint name="arm_7_joint" type="revolute">
    <origin rpy="-1.5708 0 0" xyz="0 -0.1927 0"/>
    <parent link="arm_6_link"/>
    <child link="arm_7_link"/>
    <axis xyz="0 0 1"/>
    <calibration rising="-2.34"/>
    <dynamics damping="5"/>
    <limit effort="9.6" lower="-6.2831853" upper="6.2831853" velocity="2.0"/>
    <safety_controller k_position="20" k_velocity="25" soft_lower_limit="-6.2731853" soft_upper_limit="6.2731853"/>
  </joint>
  <link name="arm_7_link">
    <inertial>
      <origin rpy="0 0 0" xyz="0 0 0"/>
      <mass value="1.120198"/>
      <inertia ixx="0.01" ixy="0" ixz="0" iyy="0.01" iyz="0" izz="0.01"/>
    </inertial>
    <visual>
      <origin rpy="0 0 0" xyz="0 0 0"/>
      <geometry>
        <mesh filename="package://schunk_description/meshes/lwa/lwa7.stl"/>
      </geometry>
      <material name="Blue"/>
    </visual>
    <collision>
      <origin rpy="0 0 0" xyz="0 0 0"/>
      <geometry>
        <mesh filename="package://schunk_description/meshes/lwa/lwa7.stlb"/>
      </geometry>
    </collision>
  </link>
  <gazebo reference="arm_0_link">
    <material value="PR2/Red"/>
    <turnGravityOff>false</turnGravityOff>
  </gazebo>
  <gazebo reference="arm_1_link">
    <material value="PR2/Blue"/>
    <turnGravityOff>false</turnGravityOff>
  </gazebo>
  <gazebo reference="arm_2_link">
    <material value="PR2/Red"/>
    <turnGravityOff>false</turnGravityOff>
  </gazebo>
  <gazebo reference="arm_3_link">
    <material value="PR2/Blue"/>
    <turnGravityOff>false</turnGravityOff>
  </gazebo>
  <gazebo reference="arm_4_link">
    <material value="PR2/Red"/>
    <turnGravityOff>false</turnGravityOff>
  </gazebo>
  <gazebo reference="arm_5_link">
    <material value="PR2/Blue"/>
    <turnGravityOff>false</turnGravityOff>
  </gazebo>
  <gazebo reference="arm_6_link">
    <material value="PR2/Red"/>
    <turnGravityOff>false</turnGravityOff>
  </gazebo>
  <gazebo reference="arm_7_link">
    <material value="PR2/Blue"/>
    <turnGravityOff>false</turnGravityOff>
  </gazebo>
  <transmission name="arm_1_trans" type="pr2_mechanism_model/SimpleTransmission">
    <actuator name="arm_1_motor"/>
    <joint name="arm_1_joint"/>
    <mechanicalReduction>1</mechanicalReduction>
  </transmission>
  <transmission name="arm_2_trans" type="pr2_mechanism_model/SimpleTransmission">
    <actuator name="arm_2_motor"/>
    <joint name="arm_2_joint"/>
    <mechanicalReduction>1</mechanicalReduction>
  </transmission>
  <transmission name="arm_3_trans" type="pr2_mechanism_model/SimpleTransmission">
    <actuator name="arm_3_motor"/>
    <joint name="arm_3_joint"/>
    <mechanicalReduction>1</mechanicalReduction>
  </transmission>
  <transmission name="arm_4_trans" type="pr2_mechanism_model/SimpleTransmission">
    <actuator name="arm_4_motor"/>
    <joint name="arm_4_joint"/>
    <mechanicalReduction>1</mechanicalReduction>
  </transmission>
  <transmission name="arm_5_trans" type="pr2_mechanism_model/SimpleTransmission">
    <actuator name="arm_5_motor"/>
    <joint name="arm_5_joint"/>
    <mechanicalReduction>1</mechanicalReduction>
  </transmission>
  <transmission name="arm_6_trans" type="pr2_mechanism_model/SimpleTransmission">
    <actuator name="arm_6_motor"/>
    <joint name="arm_6_joint"/>
    <mechanicalReduction>1</mechanicalReduction>
  </transmission>
  <transmission name="arm_7_trans" type="pr2_mechanism_model/SimpleTransmission">
    <actuator name="arm_7_motor"/>
    <joint name="arm_7_joint"/>
    <mechanicalReduction>1</mechanicalReduction>
  </transmission>
  <joint name="sdh_palm_joint" type="fixed">
    <origin rpy="0 3.14159265359 -1.57079632679" xyz="0 0 0"/>
    <parent link="arm_7_link"/>
    <child link="sdh_palm_link"/>
  </joint>
  <link name="sdh_palm_link">
    <inertial>
      <origin rpy="0 0 0" xyz="0 0 0"/>
      <mass value="1"/>
      <inertia ixx="0.01" ixy="0" ixz="0" iyy="0.01" iyz="0" izz="0.01"/>
    </inertial>
    <visual>
      <origin rpy="0 0 0" xyz="0 0 0"/>
      <geometry>
        <mesh filename="package://schunk_description/meshes/sdh/palm.stl"/>
      </geometry>
      <material name="Grey"/>
    </visual>
    <collision>
      <origin rpy="0 0 0" xyz="0 0 0"/>
      <geometry>
        <mesh filename="package://schunk_description/meshes/sdh/palm.stlb"/>
      </geometry>
    </collision>
  </link>
  <joint name="sdh_grasp_joint" type="fixed">
    <origin rpy="0 0 0" xyz="0 0 0.15"/>
    <parent link="sdh_palm_link"/>
    <child link="sdh_grasp_link"/>
  </joint>
  <link name="sdh_grasp_link"/>
  <joint name="sdh_tip_joint" type="fixed">
    <origin rpy="0 0 0" xyz="0 0 0.22"/>
    <parent link="sdh_palm_link"/>
    <child link="sdh_tip_link"/>
  </joint>
  <link name="sdh_tip_link"/>
  <joint name="sdh_knuckle_joint" type="revolute">
    <origin rpy="0 0 3.14159265" xyz="0.01905 0.033 0.0745"/>
    <parent link="sdh_palm_link"/>
    <child link="sdh_finger_11_link"/>
    <axis xyz="0 0 1"/>
    <dynamics damping="1"/>
    <limit effort="100" lower="0" upper="1.570796327" velocity="5"/>
  </joint>
  <link name="sdh_finger_11_link">
    <inertial>
      <origin rpy="0 0 0" xyz="0 0 0"/>
      <mass value="0.1"/>
      <inertia ixx="0.01" ixy="0" ixz="0" iyy="0.01" iyz="0" izz="0.01"/>
    </inertial>
    <visual>
      <origin rpy="0 0 0" xyz="0 0 0"/>
      <geometry>
        <mesh filename="package://schunk_description/meshes/sdh/knuckle.stl"/>
      </geometry>
      <material name="Black"/>
    </visual>
    <collision>
      <origin rpy="0 0 0" xyz="0 0 0"/>
      <geometry>
        <mesh filename="package://schunk_description/meshes/sdh/knuckle.stlb"/>
      </geometry>
    </collision>
  </link>
  <joint name="sdh_finger_12_joint" type="revolute">
    <origin rpy="0 0 0" xyz="0 0 0.0165"/>
    <parent link="sdh_finger_11_link"/>
    <child link="sdh_finger_12_link"/>
    <axis xyz="0 1 0"/>
    <dynamics damping="1"/>
    <limit effort="100" lower="-1.570796327" upper="1.570796327" velocity="5"/>
  </joint>
  <link name="sdh_finger_12_link">
    <inertial>
      <origin rpy="0 0 0" xyz="0 0 0"/>
      <mass value="0.1"/>
      <inertia ixx="0.01" ixy="0" ixz="0" iyy="0.01" iyz="0" izz="0.01"/>
    </inertial>
    <visual>
      <origin rpy="0 0 0" xyz="0 0 0"/>
      <geometry>
        <mesh filename="package://schunk_description/meshes/sdh/finger.stl"/>
      </geometry>
      <material name="Red"/>
    </visual>
    <collision>
      <origin rpy="0 0 0" xyz="0 0 0"/>
      <geometry>
        <mesh filename="package://schunk_description/meshes/sdh/finger.stlb"/>
      </geometry>
    </collision>
  </link>
  <joint name="sdh_finger_13_joint" type="revolute">
    <origin rpy="0 0 0" xyz="0 0 0.0865"/>
    <parent link="sdh_finger_12_link"/>
    <child link="sdh_finger_13_link"/>
    <axis xyz="0 1 0"/>
    <dynamics damping="1"/>
    <limit effort="100" lower="-1.570796327" upper="1.570796327" velocity="5"/>
  </joint>
  <link name="sdh_finger_13_link">
    <inertial>
      <origin rpy="0 0 0" xyz="0 0 0"/>
      <mass value="0.1"/>
      <inertia ixx="0.01" ixy="0" ixz="0" iyy="0.01" iyz="0" izz="0.01"/>
    </inertial>
    <visual>
      <origin rpy="0 0 0" xyz="0 0 0"/>
      <geometry>
        <mesh filename="package://schunk_description/meshes/sdh/finger_tip.stl"/>
      </geometry>
      <material name="Blue"/>
    </visual>
    <collision>
      <origin rpy="0 0 0" xyz="0 0 0"/>
      <geometry>
        <mesh filename="package://schunk_description/meshes/sdh/finger_tip.stlb"/>
      </geometry>
    </collision>
  </link>
  <joint name="sdh_finger_21_joint" type="revolute">
    <mimic joint="sdh_knuckle_joint" multiplier="1" offset="0"/>
    <origin rpy="0 0 3.14159265" xyz="0.01905 -0.033 0.0745"/>
    <parent link="sdh_palm_link"/>
    <child link="sdh_finger_21_link"/>
    <axis xyz="0 0 -1"/>
    <dynamics damping="1"/>
    <limit effort="100" lower="0" upper="1.570796327" velocity="5"/>
  </joint>
  <link name="sdh_finger_21_link">
    <inertial>
      <origin rpy="0 0 0" xyz="0 0 0"/>
      <mass value="0.1"/>
      <inertia ixx="0.01" ixy="0" ixz="0" iyy="0.01" iyz="0" izz="0.01"/>
    </inertial>
    <visual>
      <origin rpy="0 0 0" xyz="0 0 0"/>
      <geometry>
        <mesh filename="package://schunk_description/meshes/sdh/knuckle.stl"/>
      </geometry>
      <material name="Black"/>
    </visual>
    <collision>
      <origin rpy="0 0 0" xyz="0 0 0"/>
      <geometry>
        <mesh filename="package://schunk_description/meshes/sdh/knuckle.stlb"/>
      </geometry>
    </collision>
  </link>
  <joint name="sdh_finger_22_joint" type="revolute">
    <origin rpy="0 0 0" xyz="0 0 0.0165"/>
    <parent link="sdh_finger_21_link"/>
    <child link="sdh_finger_22_link"/>
    <axis xyz="0 1 0"/>
    <dynamics damping="1"/>
    <limit effort="100" lower="-1.570796327" upper="1.570796327" velocity="5"/>
  </joint>
  <link name="sdh_finger_22_link">
    <inertial>
      <origin rpy="0 0 0" xyz="0 0 0"/>
      <mass value="0.1"/>
      <inertia ixx="0.01" ixy="0" ixz="0" iyy="0.01" iyz="0" izz="0.01"/>
    </inertial>
    <visual>
      <origin rpy="0 0 0" xyz="0 0 0"/>
      <geometry>
        <mesh filename="package://schunk_description/meshes/sdh/finger.stl"/>
      </geometry>
      <material name="Red"/>
    </visual>
    <collision>
      <origin rpy="0 0 0" xyz="0 0 0"/>
      <geometry>
        <mesh filename="package://schunk_description/meshes/sdh/finger.stlb"/>
      </geometry>
    </collision>
  </link>
  <joint name="sdh_finger_23_joint" type="revolute">
    <origin rpy="0 0 0" xyz="0 0 0.0865"/>
    <parent link="sdh_finger_22_link"/>
    <child link="sdh_finger_23_link"/>
    <axis xyz="0 1 0"/>
    <dynamics damping="1"/>
    <limit effort="100" lower="-1.570796327" upper="1.570796327" velocity="5"/>
  </joint>
  <link name="sdh_finger_23_link">
    <inertial>
      <origin rpy="0 0 0" xyz="0 0 0"/>
      <mass value="0.1"/>
      <inertia ixx="0.01" ixy="0" ixz="0" iyy="0.01" iyz="0" izz="0.01"/>
    </inertial>
    <visual>
      <origin rpy="0 0 0" xyz="0 0 0"/>
      <geometry>
        <mesh filename="package://schunk_description/meshes/sdh/finger_tip.stl"/>
      </geometry>
      <material name="Blue"/>
    </visual>
    <collision>
      <origin rpy="0 0 0" xyz="0 0 0"/>
      <geometry>
        <mesh filename="package://schunk_description/meshes/sdh/finger_tip.stlb"/>
      </geometry>
    </collision>
  </link>
  <joint name="sdh_thumb_1_joint" type="fixed">
    <origin rpy="0 0 0" xyz="-0.03811 0 0.0745 "/>
    <parent link="sdh_palm_link"/>
    <child link="sdh_thumb_1_link"/>
  </joint>
  <link name="sdh_thumb_1_link">
    <inertial>
      <origin rpy="0 0 0" xyz="0 0 0"/>
      <mass value="0.1"/>
      <inertia ixx="0.01" ixy="0" ixz="0" iyy="0.01" iyz="0" izz="0.01"/>
    </inertial>
    <visual>
      <origin rpy="0 0 0" xyz="0 0 0"/>
      <geometry>
        <mesh filename="package://schunk_description/meshes/sdh/knuckle.stl"/>
      </geometry>
      <material name="Black"/>
    </visual>
    <collision>
      <origin rpy="0 0 0" xyz="0 0 0"/>
      <geometry>
        <mesh filename="package://schunk_description/meshes/sdh/knuckle.stlb"/>
      </geometry>
    </collision>
  </link>
  <joint name="sdh_thumb_2_joint" type="revolute">
    <origin rpy="0 0 0" xyz="0 0 0.0165"/>
    <parent link="sdh_thumb_1_link"/>
    <child link="sdh_thumb_2_link"/>
    <axis xyz="0 1 0"/>
    <dynamics damping="1"/>
    <limit effort="100" lower="-1.570796327" upper="1.570796327" velocity="5"/>
  </joint>
  <link name="sdh_thumb_2_link">
    <inertial>
      <origin rpy="0 0 0" xyz="0 0 0"/>
      <mass value="0.1"/>
      <inertia ixx="0.01" ixy="0" ixz="0" iyy="0.01" iyz="0" izz="0.01"/>
    </inertial>
    <visual>
      <origin rpy="0 0 0" xyz="0 0 0"/>
      <geometry>
        <mesh filename="package://schunk_description/meshes/sdh/finger.stl"/>
      </geometry>
      <material name="Red"/>
    </visual>
    <collision>
      <origin rpy="0 0 0" xyz="0 0 0"/>
      <geometry>
        <mesh filename="package://schunk_description/meshes/sdh/finger.stlb"/>
      </geometry>
    </collision>
  </link>
  <joint name="sdh_thumb_3_joint" type="revolute">
    <origin rpy="0 0 0" xyz="0 0 0.0865"/>
    <parent link="sdh_thumb_2_link"/>
    <child link="sdh_thumb_3_link"/>
    <axis xyz="0 1 0"/>
    <dynamics damping="1"/>
    <limit effort="100" lower="-1.570796327" upper="1.570796327" velocity="5"/>
  </joint>
  <link name="sdh_thumb_3_link">
    <inertial>
      <origin rpy="0 0 0" xyz="0 0 0"/>
      <mass value="0.1"/>
      <inertia ixx="0.01" ixy="0" ixz="0" iyy="0.01" iyz="0" izz="0.01"/>
    </inertial>
    <visual>
      <origin rpy="0 0 0" xyz="0 0 0"/>
      <geometry>
        <mesh filename="package://schunk_description/meshes/sdh/finger_tip.stl"/>
      </geometry>
      <material name="Blue"/>
    </visual>
    <collision>
      <origin rpy="0 0 0" xyz="0 0 0"/>
      <geometry>
        <mesh filename="package://schunk_description/meshes/sdh/finger_tip.stlb"/>
      </geometry>
    </collision>
  </link>
  <gazebo reference="sdh_palm_link">
    <material>Gazebo/Grey</material>
    <turnGravityOff>false</turnGravityOff>
  </gazebo>
  <gazebo reference="sdh_finger_11_link">
    <material>Gazebo/Black</material>
    <turnGravityOff>false</turnGravityOff>
  </gazebo>
  <gazebo reference="sdh_finger_12_link">
    <selfCollide>true</selfCollide>
    <sensor:contact name="sdh_finger_12_contact_sensor">
      <geom>sdh_finger_12_link_geom</geom>
      <updateRate>100.0</updateRate>
      <controller:gazebo_ros_bumper name="sdh_finger_12_gazebo_ros_bumper_controller" plugin="libgazebo_ros_bumper.so">
        <alwaysOn>true</alwaysOn>
        <updateRate>100.0</updateRate>
        <frameName>sdh_finger_12_link</frameName>
        <bumperTopicName>sdh_finger_12_bumper</bumperTopicName>
        <interface:bumper name="sdh_finger_12_bumper_iface"/>
      </controller:gazebo_ros_bumper>
    </sensor:contact>
    <material>Gazebo/Red</material>
    <turnGravityOff>false</turnGravityOff>
  </gazebo>
  <gazebo reference="sdh_finger_13_link">
    <selfCollide>true</selfCollide>
    <sensor:contact name="sdh_finger_13_contact_sensor">
      <geom>sdh_finger_13_link_geom</geom>
      <updateRate>100.0</updateRate>
      <controller:gazebo_ros_bumper name="sdh_finger_13_gazebo_ros_bumper_controller" plugin="libgazebo_ros_bumper.so">
        <alwaysOn>true</alwaysOn>
        <updateRate>100.0</updateRate>
        <frameName>sdh_finger_13_link</frameName>
        <bumperTopicName>sdh_finger_13_bumper</bumperTopicName>
        <interface:bumper name="sdh_finger_13_bumper_iface"/>
      </controller:gazebo_ros_bumper>
    </sensor:contact>
    <material>Gazebo/Blue</material>
  </gazebo>
  <gazebo reference="sdh_finger_21_link">
    <material>Gazebo/Black</material>
    <turnGravityOff>false</turnGravityOff>
  </gazebo>
  <gazebo reference="sdh_finger_22_link">
    <selfCollide>true</selfCollide>
    <sensor:contact name="sdh_finger_22_contact_sensor">
      <geom>sdh_finger_22_link_geom</geom>
      <updateRate>100.0</updateRate>
      <controller:gazebo_ros_bumper name="sdh_finger_22_gazebo_ros_bumper_controller" plugin="libgazebo_ros_bumper.so">
        <alwaysOn>true</alwaysOn>
        <updateRate>100.0</updateRate>
        <frameName>sdh_finger_22_link</frameName>
        <bumperTopicName>sdh_finger_22_bumper</bumperTopicName>
        <interface:bumper name="sdh_finger_22_bumper_iface"/>
      </controller:gazebo_ros_bumper>
    </sensor:contact>
    <material>Gazebo/Red</material>
    <turnGravityOff>false</turnGravityOff>
  </gazebo>
  <gazebo reference="sdh_finger_23_link">
    <selfCollide>true</selfCollide>
    <sensor:contact name="sdh_finger_23_contact_sensor">
      <geom>sdh_finger_23_link_geom</geom>
      <updateRate>100.0</updateRate>
      <controller:gazebo_ros_bumper name="sdh_finger_23_gazebo_ros_bumper_controller" plugin="libgazebo_ros_bumper.so">
        <alwaysOn>true</alwaysOn>
        <updateRate>100.0</updateRate>
        <frameName>sdh_finger_23_link</frameName>
        <bumperTopicName>sdh_finger_23_bumper</bumperTopicName>
        <interface:bumper name="sdh_finger_23_bumper_iface"/>
      </controller:gazebo_ros_bumper>
    </sensor:contact>
    <material>Gazebo/Blue</material>
  </gazebo>
  <gazebo reference="sdh_thumb_1_link">
    <material>Gazebo/Black</material>
    <turnGravityOff>false</turnGravityOff>
  </gazebo>
  <gazebo reference="sdh_thumb_2_link">
    <selfCollide>true</selfCollide>
    <sensor:contact name="sdh_thumb_2_contact_sensor">
      <geom>sdh_thumb_2_link_geom</geom>
      <updateRate>100.0</updateRate>
      <controller:gazebo_ros_bumper name="sdh_thumb_2_gazebo_ros_bumper_controller" plugin="libgazebo_ros_bumper.so">
        <alwaysOn>true</alwaysOn>
        <updateRate>100.0</updateRate>
        <frameName>sdh_thumb_2_link</frameName>
        <bumperTopicName>sdh_thumb_2_bumper</bumperTopicName>
        <interface:bumper name="sdh_thumb_2_bumper_iface"/>
      </controller:gazebo_ros_bumper>
    </sensor:contact>
    <material>Gazebo/Red</material>
    <turnGravityOff>false</turnGravityOff>
  </gazebo>
  <gazebo reference="sdh_thumb_3_link">
    <selfCollide>true</selfCollide>
    <sensor:contact name="sdh_thumb_3_contact_sensor">
      <geom>sdh_thumb_3_link_geom</geom>
      <updateRate>100.0</updateRate>
      <controller:gazebo_ros_bumper name="sdh_thumb_3_gazebo_ros_bumper_controller" plugin="libgazebo_ros_bumper.so">
        <alwaysOn>true</alwaysOn>
        <updateRate>100.0</updateRate>
        <frameName>sdh_thumb_3_link</frameName>
        <bumperTopicName>sdh_thumb_3_bumper</bumperTopicName>
        <interface:bumper name="sdh_thumb_3_bumper_iface"/>
      </controller:gazebo_ros_bumper>
    </sensor:contact>
    <material>Gazebo/Blue</material>
  </gazebo>
  <transmission name="sdh_knuckle_trans" type="pr2_mechanism_model/SimpleTransmission">
    <actuator name="sdh_knuckle_motor"/>
    <joint name="sdh_finger_21_joint"/>
    <mechanicalReduction>1</mechanicalReduction>
  </transmission>
  <transmission name="sdh_knuckle_trans" type="pr2_mechanism_model/SimpleTransmission">
    <actuator name="sdh_knuckle_motor"/>
    <joint name="sdh_knuckle_joint"/>
    <mechanicalReduction>1</mechanicalReduction>
  </transmission>
  <transmission name="sdh_finger_12_trans" type="pr2_mechanism_model/SimpleTransmission">
    <actuator name="sdh_finger_12_motor"/>
    <joint name="sdh_finger_12_joint"/>
    <mechanicalReduction>1</mechanicalReduction>
  </transmission>
  <transmission name="sdh_finger_13_trans" type="pr2_mechanism_model/SimpleTransmission">
    <actuator name="sdh_finger_13_motor"/>
    <joint name="sdh_finger_13_joint"/>
    <mechanicalReduction>1</mechanicalReduction>
  </transmission>
  <transmission name="sdh_finger_22_trans" type="pr2_mechanism_model/SimpleTransmission">
    <actuator name="sdh_finger_22_motor"/>
    <joint name="sdh_finger_22_joint"/>
    <mechanicalReduction>1</mechanicalReduction>
  </transmission>
  <transmission name="sdh_finger_23_trans" type="pr2_mechanism_model/SimpleTransmission">
    <actuator name="sdh_finger_23_motor"/>
    <joint name="sdh_finger_23_joint"/>
    <mechanicalReduction>1</mechanicalReduction>
  </transmission>
  <transmission name="sdh_thumb_2_trans" type="pr2_mechanism_model/SimpleTransmission">
    <actuator name="sdh_thumb_2_motor"/>
    <joint name="sdh_thumb_2_joint"/>
    <mechanicalReduction>1</mechanicalReduction>
  </transmission>
  <transmission name="sdh_thumb_3_trans" type="pr2_mechanism_model/SimpleTransmission">
    <actuator name="sdh_thumb_3_motor"/>
    <joint name="sdh_thumb_3_joint"/>
    <mechanicalReduction>1</mechanicalReduction>
  </transmission>
  <!-- tof camera -->
  <joint name="tof_joint" type="fixed">
    <origin rpy="0 -0.17 0" xyz="-0.825 0 0.723"/>
    <parent link="base_link"/>
    <child link="tof_link"/>
  </joint>
  <link name="tof_link">
    <inertial>
      <mass value="0.01"/>
      <origin rpy="0 0 0" xyz="0 0 0"/>
      <inertia ixx="0.0001" ixy="0" ixz="0" iyy="0.0001" iyz="0" izz="0.0001"/>
    </inertial>
    <visual>
      <origin rpy="0 0 0" xyz="0 0 0.015"/>
      <geometry>
        <box size="0.02 0.02 0.075"/>
      </geometry>
      <material name="Red"/>
    </visual>
    <collision>
      <origin rpy="0 0 0" xyz="0 0 0.015"/>
      <geometry>
        <box size="0.02 0.02 0.075"/>
      </geometry>
    </collision>
  </link>
  <joint name="tof_frame_joint" type="fixed">
    <origin rpy="1.5708 -1.5708 0" xyz="0 0 0"/>
    <parent link="tof_link"/>
    <child link="tof_frame"/>
  </joint>
  <link name="tof_frame">
    <inertial>
      <mass value="0.01"/>
      <origin rpy="0 0 0" xyz="0 0 0"/>
      <inertia ixx="0.0001" ixy="0" ixz="0" iyy="0.0001" iyz="0" izz="0.0001"/>
    </inertial>
    <visual>
      <origin rpy="0 0 0" xyz="0 0 0"/>
      <geometry>
        <box size="0.01 0.01 0.01"/>
      </geometry>
      <material name="Red"/>
    </visual>
    <collision>
      <origin rpy="0 0 0" xyz="0 0 0"/>
      <geometry>
        <box size="0.01 0.01 0.01"/>
      </geometry>
    </collision>
  </link>
  <gazebo reference="tof_frame">
    <sensor:ray name="tof_sensor">
      <rayCount>176</rayCount>
      <!--true value 176-->
      <rangeCount>176</rangeCount>
      <laserCount>1</laserCount>
      <origin>0.0 0.0 0.05</origin>
      <displayRays>false</displayRays>
      <minAngle>-21.8</minAngle>
      <maxAngle>21.8</maxAngle>
      <minRange>0.80</minRange>
      <!--0.8m min calibrated range-->
      <maxRange>5.0</maxRange>
      <!--5.0m max calibrated range-->
      <resRange>0.010</resRange>
      <updateRate>10</updateRate>
      <!--max50Hz-->
      <verticalRayCount>144</verticalRayCount>
      <!--true value 144 -->
      <verticalRangeCount>144</verticalRangeCount>
      <verticalMinAngle>-17.3</verticalMinAngle>
      <verticalMaxAngle>17.3</verticalMaxAngle>
      <controller:gazebo_ros_block_laser name="tof_controller" plugin="libgazebo_ros_block_laser.so">
        <gaussianNoise>0.005</gaussianNoise>
        <alwaysOn>true</alwaysOn>
        <updateRate>30</updateRate>
        <!--max 50Hz, cob3 30Hz -->
        <topicName>/tof/point_cloud2</topicName>
        <frameName>/tof_frame</frameName>
        <interface:laser name="tof_ray_block_iface"/>
      </controller:gazebo_ros_block_laser>
    </sensor:ray>
    <material value="Gazebo/Red"/>
    <turnGravityOff>true</turnGravityOff>
  </gazebo>
</robot>
